Workbook

Sheet Comparison
A1: # | B1: Original ID | C1: Review (shortened) | D1: VADER score | E1: VADER label | F1: My grade | G1: Result | H1: Why they differ / notes
A2: 1 | B2: 1 | C2: It looks soft and comfortable to use. Appearance is quite good, nice to look and stylish | E2: Good | F2: Good | G2: =IF(E2=F2,"Match","Mismatch") -> Match
A3: 2 | B3: 2201 | C3: super comfortable good 38 to 40 size | E3: Good | F3: Good | G3: =IF(E3=F3,"Match","Mismatch") -> Match
A4: 3 | B4: 2202 | C4: Maganda, makapal, at pwede ipang araw araw na isuot. Will order again. Thank you seller | E4: Good | F4: Good | G4: =IF(E4=F4,"Match","Mismatch") -> Match
A5: 4 | B5: 2203 | C5: Thanks sa mabait na rider and seller | E5: Good | F5: Good | G5: =IF(E5=F5,"Match","Mismatch") -> Match
A6: 5 | B6: 2204 | C6: Ganda ng quality po | D6: 0.5423 | E6: Good | F6: Good | G6: =IF(E6=F6,"Match","Mismatch") -> Match
A7: 6 | B7: 2205 | C7: good god Good | D7: 0.7783 | E7: Good | F7: Good | G7: =IF(E7=F7,"Match","Mismatch") -> Match
A8: 7 | B8: 2206 | C8: Wrong item naman nakakadisapoint... naging pangtrabaho na ng asawa ko ang haba | D8: -0.5423 | E8: Bad | F8: Bad | G8: =IF(E8=F8,"Match","Mismatch") -> Match
A9: 8 | B9: 2207 | C9: Nipis naman ng item | D9: -0.3612 | E9: Bad | F9: Bad | G9: =IF(E9=F9,"Match","Mismatch") -> Match
A10: 9 | B10: 2208 | C10: iba pinadala, hindi naman knee socks | D10: 0 | E10: Neutral | F10: Bad | G10: =IF(E10=F10,"Match","Mismatch") -> Mismatch | H10: Wrong item sent; VADER has no lexicon hit for 'iba pinadala' / 'hindi naman' so scored 0
A11: 10 | B11: 2209 | C11: Hindi un inorder ko malalaki ung dumating | D11: 0 | E11: Neutral | F11: Bad | G11: =IF(E11=F11,"Match","Mismatch") -> Mismatch | H11: Wrong item received; negative complaint with no sentiment words
A12: 11 | B12: 2210 | C12: Thank.you seller | D12: 0.25 | E12: Good | F12: Good | G12: =IF(E12=F12,"Match","Mismatch") -> Match | H12: Mild thanks only
A13: 12 | B13: 2211 | C13: compostable to wear, cotton soft and breathable... rider is very kind. will order again. | D13: 0.9022 | E13: Good | F13: Good | G13: =IF(E13=F13,"Match","Mismatch") -> Match
A14: 13 | B14: 2212 | C14: Thank you! Buti na lang nabibili na lahat sa shopee... Okay naman ang products! | D14: 0.555 | E14: Good | F14: Good | G14: =IF(E14=F14,"Match","Mismatch") -> Match
A15: 14 | B15: 2213 | C15: Received na po. Good quality, complete, correct. Always satisfied. Thank you po | D15: 0.8176 | E15: Good | F15: Good | G15: =IF(E15=F15,"Match","Mismatch") -> Match
A16: 15 | B16: 2214 | C16: Maganda ang quality ng items. Medyo hindi nagustuhan ang packaging, madumi ang plastic... | D16: 0.2018 | E16: Good | F16: Good | G16: =IF(E16=F16,"Match","Mismatch") -> Match | H16: Mixed but mostly positive; packaging only a minor complaint
A17: 16 | B17: 2215 | C17: Good products. I was satisfied! It's great and ayos lahat ng items. Thank you seller | D17: 0.9918 | E17: Good | F17: Good | G17: =IF(E17=F17,"Match","Mismatch") -> Match
A18: 17 | B18: 2216 | C18: Still smooth transaction, 2nd order, kompleto... will order again. | D18: 0.8316 | E18: Good | F18: Good | G18: =IF(E18=F18,"Match","Mismatch") -> Match
A19: 18 | B19: 2217 | C19: Wala po akong masabi ang gaganda po ng shorts... Thank you po sa freebie | D19: 0.9709 | E19: Good | F19: Good | G19: =IF(E19=F19,"Match","Mismatch") -> Match
A20: 19 | B20: 2218 | C20: still satisfied from this shop, complete order and color... satisfied ako lage | D20: 0.9788 | E20: Good | F20: Good | G20: =IF(E20=F20,"Match","Mismatch") -> Match
A21: 20 | B21: 2219 | C21: Ang ganda ng quality ang bait din ni seller thank you po tama lahat ng dumating | D21: 0.9042 | E21: Good | F21: Good | G21: =IF(E21=F21,"Match","Mismatch") -> Match
A22: 21 | B22: 2220 | C22: Complete orders with correct variations. Ganda talaga ng mga shorts nyu... Sobrang nagustuhan ko | D22: 0.9856 | E22: Good | F22: Good | G22: =IF(E22=F22,"Match","Mismatch") -> Match
A23: 22 | B23: 2221 | C23: Maganda yung tela and mabilis delivery. | D23: 0.743 | E23: Good | F23: Good | G23: =IF(E23=F23,"Match","Mismatch") -> Match
A24: 23 | B24: 2222 | C24: Thank u so much po! Maayos po at makapal ung tela | D24: 0.6476 | E24: Good | F24: Good | G24: =IF(E24=F24,"Match","Mismatch") -> Match
A25: 24 | B25: 2223 | C25: Thank u. Sakto lahat ng dumating at maganda po | D25: 0.743 | E25: Good | F25: Good | G25: =IF(E25=F25,"Match","Mismatch") -> Match
A26: 25 | B26: 2224 | C26: Maganda. Nagustuhan ng anak q kya order aq ulit... Thanks seller, shopee at J&T | D26: 0.8674 | E26: Good | F26: Good | G26: =IF(E26=F26,"Match","Mismatch") -> Match
A27: 26 | B27: 2225 | C27: Legiiiit Ang ganda ng mga items. Recommended shop | D27: 0.9477 | E27: Good | F27: Good | G27: =IF(E27=F27,"Match","Mismatch") -> Match
A28: 27 | B28: 2226 | C28: hagagvabajjajansjsjsj... very very very nice jjajsnsjs | D28: 0.6206 | E28: Good | F28: Good | G28: =IF(E28=F28,"Match","Mismatch") -> Match | H28: Mostly keyboard-mash; only real content is 'very very very nice'
A29: 28 | B29: 2227 | C29: Maganda maganda, lagi akong oorder sa shop na to... Salamat salamat | D29: 0.925 | E29: Good | F29: Good | G29: =IF(E29=F29,"Match","Mismatch") -> Match
A30: 29 | B30: 2228 | C30: Mabilis nadeliver, maayos ang packaging. Sa susunod ulit na order, ibang kulay naman. Salamat | D30: 0.8934 | E30: Good | F30: Good | G30: =IF(E30=F30,"Match","Mismatch") -> Match
A31: 30 | B31: 2229 | C31: Maganda po ang items, maayos ang pagkakapack... mali ang isang short pero mabebenta ko naman | D31: 0.7351 | E31: Good | F31: Good | G31: =IF(E31=F31,"Match","Mismatch") -> Match | H31: One wrong item, but overall positive
A32: 31 | B32: 2230 | C32: 17 days bago dumating. .parang overseas. | D32: 0 | E32: Neutral | F32: Bad | G32: =IF(E32=F32,"Match","Mismatch") -> Mismatch | H32: Complaint about slow delivery (sarcastic comparison); no sentiment words for VADER
A33: 32 | B33: 2231 | C33: Cloth is thin Material Not bad | D33: 0.431 | E33: Good | F33: Neutral | G33: =IF(E33=F33,"Match","Mismatch") -> Mismatch | H33: 'Not bad' is a negation; VADER read 'bad' as +1.9. Lukewarm, so Neutral
A34: 33 | B34: 2232 | C34: mukhang hindi gawa ng hanford | D34: 0 | E34: Neutral | F34: Bad | G34: =IF(E34=F34,"Match","Mismatch") -> Mismatch | H34: Says item looks fake / not from the brand; implied negative
A35: 34 | B35: 2233 | C35: Low quality | D35: -0.5423 | E35: Bad | F35: Bad | G35: =IF(E35=F35,"Match","Mismatch") -> Match
A36: 35 | B36: 2234 | C36: Wrong size | D36: -0.4588 | E36: Bad | F36: Bad | G36: =IF(E36=F36,"Match","Mismatch") -> Match
A37: 36 | B37: 2235 | C37: The seller send me the Wrong size. Instead of Small, they send Large. | D37: -0.4588 | E37: Bad | F37: Bad | G37: =IF(E37=F37,"Match","Mismatch") -> Match
A38: 37 | B38: 2236 | C38: the product works... charging problem, cleaned it and it worked... I like the lights. Product good for its price | D38: 0.3071 | E38: Good | F38: Good | G38: =IF(E38=F38,"Match","Mismatch") -> Match | H38: Mixed story, but ends positive
A39: 38 | B39: 2237 | C39: wrong item received. Ordered M10 I received F9. Poor quality... hassle to request a refund | D39: -0.9153 | E39: Bad | F39: Bad | G39: =IF(E39=F39,"Match","Mismatch") -> Match
A40: 39 | B40: 2238 | C40: hindi nagana Product hindi nagana bad | D40: 0.431 | E40: Good | F40: Bad | G40: =IF(E40=F40,"Match","Mismatch") -> Mismatch | H40: Says it doesn't work; VADER's 'bad' +1.9 is a lexicon error and outweighed the negation
...

Sheet Summary
A1: VADER vs. manual grading
A3: Total reviews | B3: =COUNTA(Comparison!$A$2:$A$114) -> 113
A4: Matches | B4: =COUNTIF(Comparison!$G$2:$G$114,"Match") -> 95
A5: Mismatches | B5: =COUNTIF(Comparison!$G$2:$G$114,"Mismatch") -> 18
A6: Agreement rate | B6: =B4/B3 -> 0.84070796
A8: Confusion matrix (rows = my grade, columns = VADER label)
A9: My grade \ VADER | B9: Good | C9: Neutral | D9: Bad | E9: Total
A10: Good | B10: =COUNTIFS(Comparison!$F$2:$F$114,$A10,Comparison!$E$2:$E$114,B$9) -> 44 | C10: =COUNTIFS(Comparison!$F$2:$F$114,$A10,Comparison!$E$2:$E$114,C$9) -> 0 | D10: =COUNTIFS(Comparison!$F$2:$F$114,$A10,Comparison!$E$2:$E$114,D$9) -> 1 | E10: =SUM(B10:D10) -> 45
A11: Neutral | B11: =COUNTIFS(Comparison!$F$2:$F$114,$A11,Comparison!$E$2:$E$114,B$9) -> 4 | C11: =COUNTIFS(Comparison!$F$2:$F$114,$A11,Comparison!$E$2:$E$114,C$9) -> 0 | D11: =COUNTIFS(Comparison!$F$2:$F$114,$A11,Comparison!$E$2:$E$114,D$9) -> 0 | E11: =SUM(B11:D11) -> 4
A12: Bad | B12: =COUNTIFS(Comparison!$F$2:$F$114,$A12,Comparison!$E$2:$E$114,B$9) -> 4 | C12: =COUNTIFS(Comparison!$F$2:$F$114,$A12,Comparison!$E$2:$E$114,C$9) -> 9 | D12: =COUNTIFS(Comparison!$F$2:$F$114,$A12,Comparison!$E$2:$E$114,D$9) -> 51 | E12: =SUM(B12:D12) -> 64
A13: Total | B13: =SUM(B10:B12) -> 52 | C13: =SUM(C10:C12) -> 9 | D13: =SUM(D10:D12) -> 52 | E13: =SUM(E10:E12) -> 113
A15: VADER Neutral that I graded Bad | B15: =COUNTIFS(Comparison!$E$2:$E$114,"Neutral",Comparison!$F$2:$F$114,"Bad") -> 9
A16: VADER Good that I graded Bad | B16: =COUNTIFS(Comparison!$E$2:$E$114,"Good",Comparison!$F$2:$F$114,"Bad") -> 4
A17: VADER Good that I graded Neutral | B17: =COUNTIFS(Comparison!$E$2:$E$114,"Good",Comparison!$F$2:$F$114,"Neutral") -> 4
A18: VADER Bad that I graded Good | B18: =COUNTIFS(Comparison!$E$2:$E$114,"Bad",Comparison!$F$2:$F$114,"Good") -> 1
A20: Notes: 'My grade' is my own reading of each review, not ground truth. Review text is shortened for readability; scores and labels are from your VADER output. Rows 1, 2, 3, 4 had no score in the data.
